<?xml version="1.0"?>
<robot name="human_like_arm">

  <!-- Base link (torso connection) -->
  <link name="base_link">
    <visual>
      <geometry>
        <cylinder radius="0.12" length="0.05"/>
      </geometry>
      <material name="gray">
        <color rgba="0.6 0.6 0.6 1"/>
      </material>
      <origin xyz="0 0 0" rpy="0 0 0"/>
    </visual>
  </link>

  <!-- Upper Arm -->
  <link name="upper_arm">
    <visual>
      <geometry>
        <cylinder radius="0.06" length="0.35"/>
      </geometry>
      <material name="skin_tone">
        <color rgba="1 0.8 0.6 1"/>
      </material>
      <!-- Cylinder centered along its length, so shift it half length -->
      <origin xyz="0 0 0.175" rpy="0 0 0"/>
    </visual>
  </link>

  <!-- Shoulder yaw joint (rotation around vertical z) -->
  <joint name="shoulder_yaw" type="revolute">
    <parent link="base_link"/>
    <child link="upper_arm"/>
    <origin xyz="0 0 0" rpy="0 0 0"/>
    <axis xyz="0 0 1"/>
    <limit lower="-3.14" upper="3.14" effort="20" velocity="1.5"/>
  </joint>

  <!-- Forearm -->
  <link name="forearm">
    <visual>
      <geometry>
        <cylinder radius="0.05" length="0.3"/>
      </geometry>
      <material name="skin_tone">
        <color rgba="1 0.8 0.6 1"/>
      </material>
      <origin xyz="0 0 0.15" rpy="0 0 0"/>
    </visual>
  </link>

  <!-- Shoulder pitch joint (rotation around lateral y) -->
  <joint name="shoulder_pitch" type="revolute">
    <parent link="upper_arm"/>
    <child link="forearm"/>
    <origin xyz="0 0 0.35" rpy="0 0 0"/>
    <axis xyz="0 1 0"/>
    <limit lower="-1.57" upper="1.57" effort="20" velocity="1.5"/>
  </joint>

  <!-- Hand -->
  <link name="hand">
    <visual>
      <geometry>
        <sphere radius="0.06"/>
      </geometry>
      <material name="skin_tone">
        <color rgba="1 0.8 0.6 1"/>
      </material>
      <origin xyz="0 0 0" rpy="0 0 0"/>
    </visual>
  </link>

  <!-- Elbow joint (rotation around lateral y) -->
  <joint name="elbow" type="revolute">
    <parent link="forearm"/>
    <child link="hand"/>
    <origin xyz="0 0 0.3" rpy="0 0 0"/>
    <axis xyz="0 1 0"/>
    <limit lower="0" upper="2.0" effort="20" velocity="2.0"/>
  </joint>

</robot>
